Workbook
Name AT_s: Summary!$D$9
Name CT_s: Summary!$D$5
Name DELAY_DWELL_S: Parameters!$B$10
Name DEPOT_LAT: Parameters!$B$6
Name DEPOT_LON: Parameters!$B$7
Name DEPOT_RADIUS_M: Parameters!$B$8
Name DT_s: Summary!$D$8
Name MAX_GAP_S: Parameters!$B$11
Name NP_s: Summary!$D$14
Name OD_s: Summary!$D$12
Name OT_s: Summary!$D$11
Name PT_s: Summary!$D$15
Name SB_s: Summary!$D$10
Name SERVICE_END: Parameters!$B$13
Name SERVICE_LAST_WEEKDAY: Parameters!$B$14
Name SERVICE_START: Parameters!$B$12
Name SPEED_STOP_MPS: Parameters!$B$5
Name ST_s: Summary!$D$7
Name STANDBY_DWELL_S: Parameters!$B$9
Name UNOBS_s: Summary!$D$18
Name UNOBS_SB_s: Summary!$D$20
Name UNOBS_UT_s: Summary!$D$19
Name UT_s: Summary!$D$6
Name UTC_OFFSET_H: Parameters!$B$15
Name WINDOW_END: Parameters!$B$17
Name WINDOW_START: Parameters!$B$16
Name WT_s: Summary!$D$13

Sheet Overview
A1: GMG Time Utilisation Model: layer documentation for the nUWAy fleet dashboard
A3: Purpose | B3: Documents each classification layer of the GMG Time Utilisation Model (2020 guideline) against the telemetry we actually hold, so /api/metrics can be built layer by layer with no ambiguity about what is measured, what is assumed and what is missing.
A4: Sources | B4: docs/GMG Time Utilisation Model.md and docs/GMG-time-utilisation-model.pdf (layer and KPI definitions); docs/data-schema.md (positions table); docs/api.md; config/app.yaml and config/vehicles.yaml; data/sample/*.csv and GPS_Report/data/*.csv.
A5: Sheets | B5: Layers: one row per layer with definition, equation, Excel formula, feasibility, dependencies and implementation method. KPIs: the GMG ratios with live values. Fields: which columns exist in which file. Future inputs: what to ask the client for. Parameters: every threshold, as named cells. Classification: the real 5-second track classified row by row with live formulas. Summary: bucket totals and reconciliation.
A6: How to use | B6: Open Parameters and set the roster, depot and dwell values. Everything else recalculates. To classify a different export, paste its timestamp/lat/lon/speed/gps_status columns into Classification A, D, E, F, G and fill the formula columns down.
A7: Feasibility legend | B7: Yes = computable from the positions table alone. Yes (config) = computable once a configuration value the client can state today is added. Partial (heuristic) = computable from position and speed with stated assumptions; will be refined by future inputs. Derived (inherits) = an identity of other layers, no worse than its inputs. No (external data) = needs a data source we do not have.
A8: Interval convention | B8: Each sample owns the interval from its timestamp to the next sample's timestamp (dt_s). The interval is classified from the sample at its start. The last sample owns nothing. Reporting-window time with no samples is 'unobserved' and is split by the roster (UT outside, SB inside).
A9: Note on the source documents | B9: In docs/GMG-time-utilisation-model.pdf (and the version of the markdown committed in de73cfd) the headings from Operating Time down are shifted one step against their bodies: the text under 'Operating Time' describes Standby, and so on. The markdown working copy was corrected on 2026-09-08. This workbook uses the standard GMG pairing, which matches the equations in the bodies (OT = AT - SB, WT = OT - OD, PT = WT - NP).
A11: Layer tree
A12: Calendar Time (CT) | B12: Yes
A13: Unscheduled Time (UT) | B13: Yes (config)
A14: Scheduled Time (ST) = CT - UT | B14: Derived (inherits)
A15: Downtime (DT) | B15: No (external data)
A16: Available Time (AT) = ST - DT | B16: Derived (inherits)
A17: Standby (SB) = SBO + SBE | B17: Partial (heuristic)
A18: Operating Time (OT) = AT - SB | B18: Partial (heuristic)
A19: Operating Delay (OD) | B19: Partial (heuristic)
A20: Working Time (WT) = OT - OD | B20: Partial (heuristic)
A21: Non-Productive Time (NP) | B21: No (external data)
A22: Productive Time (PT) = WT - NP | B22: No (external data)

Sheet Layers
A1: GMG Time Utilisation Model: layer by layer
A2: One row per classification layer, top of the tree first. 'Excel formula' is the exact formula used on the Summary sheet; 'Sample value' is live from that sheet. Feasibility refers to the datasets in data/sample and GPS_Report/data plus what config/ already holds.
A4: Layer | B4: Code | C4: Parent | D4: GMG definition | E4: nUWAy examples | F4: Equation | G4: Excel formula (Summary sheet) | H4: Feasible with current data? | I4: Dataset fields needed | J4: Depends on layers | K4: External input needed | L4: How to implement from the dataset | M4: Assumptions and caveats | N4: Sample value (s) | O4: Sample value (h)
A5: Calendar Time | B5: CT | C5: (root) | D5: All the time there is in the reporting window. 8,760 h per year (8,784 in a leap year, treated as negligible). Also called nominal time. Every other layer partitions it. | E5: A Perth day selected on the dashboard calendar = 24 h. A week = 168 h. Per vehicle, so a two-shuttle fleet has 48 h of CT per day. | F5: CT = window end - window start | G5: =IF(AND(WINDOW_START<>"",WINDOW_END<>""),(WINDOW_END-WINDOW_START)*86400,SUM(Classification!$H:$H)) -> 2247.0107 | H5: Yes | I5: timestamp (only to bound the data when no explicit window is given) | J5: none | K5: none. The reporting window comes from the query (from/to on GET /api/positions), not from the data. | L5: 1. Take the window from the request, expanded to whole Perth days exactly as docs/data-schema.md section 4 describes (a bare date d => d-1T16:00:00Z .. dT15:59:59.999999Z). 2. CT_s = (to - from) in seconds. Do NOT use last sample - first sample: a day with three hours of telemetry still has 24 h of CT, and the other 21 h have to land in UT / SB / DT. 3. Clip every classified interval to the window so an interval that straddles midnight is only counted on one day. In the workbook the WINDOW_* parameters are blank so CT falls back to the span of the sample. | M5: Leap seconds and DST are irrelevant (Perth has no DST; timestamps are UTC). Sub-second precision must be preserved: truncating to seconds collides rows (data-schema.md). | N5: =CT_s -> 2247.0107 | O5: =CT_s/3600 -> 0.62416964
A6: Unscheduled Time | B6: UT | C6: CT | D6: Time the asset is not assigned at all because nothing requires it: planned shutdowns, holidays not worked, no work available, mobilisation/demobilisation, major rebuilds. The machine's condition is irrelevant. | E6: Nights, weekends, semester breaks, public holidays, days the shuttle is not rostered, a week the shuttle is loaned to another campus. | F6: UT = CT - ST (measured directly as time outside the roster) | G6: =SUMIFS(Classification!$H:$H,Classification!$S:$S,"UT")+UNOBS_UT_s -> 0 | H6: Yes (config) | I6: timestamp (converted to Perth local time) | J6: CT | K6: Service roster: daily start/end per weekday plus an exceptions list (public holidays, non-service dates). Not in any dataset. Proposed home: config/app.yaml service_hours block, mirroring how vehicles.yaml already holds identity. | L6: 1. Convert each timestamp to Perth (UTC+8), see Classification!C. 2. in_service = weekday <= SERVICE_LAST_WEEKDAY AND SERVICE_START <= time-of-day < SERVICE_END (Classification!J). Extend with a holiday table when the client supplies one. 3. Any interval whose start is outside the roster is UT regardless of what the vehicle was doing. 4. Time inside the window but with no telemetry at all (before first / after last sample, or a gap) must also be split by the roster: outside roster => UT. The backend should walk the roster minute by minute; the workbook approximates by testing WINDOW_START only (Summary!UNOBS_UT). Heuristic fallback when no roster exists: a calendar day with zero telemetry for the vehicle is UT. This cannot tell a day off from a day in the workshop, so label it as such. | M6: Without the roster every 24 h day looks scheduled and Effective Utilisation collapses to a few percent. The sample (Thursday 16:21 to 16:58 Perth) sits inside the placeholder 08:00 to 18:00 window so UT = 0 in the example. | N6: =UT_s -> 0 | O6: =UT_s/3600 -> 0
A7: Scheduled Time | B7: ST | C7: CT | D7: Time the asset is required to meet the business plan and is assigned to an operation, project or job. | E7: Rostered service hours, e.g. 08:00 to 18:00 on weekdays during semester. | F7: ST = CT - UT | G7: =CT_s-UT_s -> 2247.0107 | H7: Derived (inherits) | I7: none directly | J7: CT, UT | K7: Inherits the roster requirement from UT. | L7: Identity. No classification of its own; every scheduled second is then split into DT, SB, OD, NP or PT by the layers below. | M7: Only as good as UT. If UT is approximated ST is approximated. | N7: =ST_s -> 2247.0107 | O7: =ST_s/3600 -> 0.62416964
A8: Downtime | B8: DT | C8: ST | D8: The operation wants the asset but it is not in a condition to perform its function. Kept as one undivided bucket in the 2020 guideline (no consensus on planned vs unplanned maintenance split; that belongs in a CMMS). | E8: Shuttle in the workshop during service hours, LiDAR fault, flat traction battery, software update that takes the vehicle out of service, waiting for a technician. | F8: DT = ST - AT (measured from a maintenance / fault log) | G8: =SUMIFS(Classification!$H:$H,Classification!$S:$S,"DT") -> 0 | H8: No (external data) | I8: none in the positions table can establish condition. battery_percent (empty in the real data) could flag 'flat' if it were populated. | J8: ST | K8: Maintenance / fault log with (vehicle_id, start, end, cause). Could be a CMMS export, a manual sheet, or derived from the still-unspecified events feed if disengagements carry a 'fault' cause and a matching re-engage. | L8: 1. Join the log to the window: for each log entry overlapping [from, to], mark every sample interval inside [start, end] as DT (Classification!R override column). 2. DT_s = SUMIFS over state = DT. 3. Unobserved time inside the roster is SB by default; a log entry converts it to DT. Until a log exists, report DT = 0 and label Available Time and every availability KPI as 'assumes zero downtime'. Do not infer DT from telemetry gaps: a silent shuttle is more often parked than broken, and GMG says condition, not signal, defines this bucket. | M8: With DT forced to 0, Mechanical Availability is 100% by construction and Uptime equals Physical Availability. These should be hidden or flagged on the dashboard until a log exists. | N8: =DT_s -> 0 | O8: =DT_s/3600 -> 0
A9: Available Time | B9: AT | C9: ST | D9: Required AND fit for duty. About condition, not use: an idle but serviceable machine is still available. | E9: Every rostered second the shuttle is not in the workshop, whether or not it is moving. | F9: AT = ST - DT | G9: =ST_s-DT_s -> 2247.0107 | H9: Derived (inherits) | I9: none directly | J9: ST, DT | K9: Inherits the maintenance log requirement from DT. | L9: Identity. Computable today only under the explicit assumption DT = 0, in which case AT = ST. | M9: Report as 'AT (assuming no downtime)' until DT is real. | N9: =AT_s -> 2247.0107 | O9: =AT_s/3600 -> 0.62416964
A10: Standby | B10: SB | C10: AT | D10: Available but not operating. SB = SBO + SBE. Operating standby (SBO): no immediate intent to run for reasons within management control (no operator, shift change, crib breaks, meetings, training, no assignment). External standby (SBE): required and committed but blocked from outside (client suspends work, area closed, site-wide weather or power loss, workforce shortage). For a contractor SBE is the billable 'off hours' state. | E10: Parked at the depot mid-roster: safety operator at lunch, waiting for the afternoon run, charging between runs. SBE: campus closed for a storm, route closed for an event. | F10: SB = AT - OT (measured as stationary inside the depot geofence for >= dwell) | G10: =SUMIFS(Classification!$H:$H,Classification!$S:$S,"SB")+UNOBS_SB_s -> 41.184775 | H10: Partial (heuristic) | I10: timestamp, latitude, longitude, speed_mps; gps_status to trust the position (positions_2.csv and sample-track.csv have no gps_status) | J10: AT (and UT, to restrict to the roster) | K10: Depot geofence (DEPOT_LAT/LON/RADIUS_M) and a dwell threshold (STANDBY_DWELL_S), both config. Splitting SBO from SBE needs reason codes (operator roster, closure notices), which no dataset has. | L10: 1. stationary = speed_mps < SPEED_STOP_MPS (Classification!K). Use the reported speed rather than differencing positions: GPS jitter at rest produces phantom movement of ~1 m per sample. 2. in_depot = haversine(lat, lon, DEPOT) <= DEPOT_RADIUS_M (Classification!I, L). 3. Group consecutive samples with the same (stationary, in_depot) into runs (Classification!O) and compute each run's total duration (Classification!P) so the test applies to the whole run, including its first samples. 4. A run that is stationary AND in_depot AND lasts >= STANDBY_DWELL_S is SB for its whole length. Shorter depot stops are WT (boarding / about to depart). 5. A telemetry gap (> MAX_GAP_S) whose last sample was in the depot is SB: the shuttle was switched off at base. Unobserved roster time with no samples at all is SB for the same reason. 6. Populated battery_percent rising while stationary would confirm charging = SB; the real feed does not populate it yet. Report SB as a single figure; do not attempt SBO/SBE without reason codes. | M10: A shuttle parked at a terminus stop that is not the depot will be counted as OD, not SB, unless a second geofence is added; STANDBY_DWELL_S and DEPOT_RADIUS_M are placeholders. In the sample the only qualifying run is the first 41 s before departure. | N10: =SB_s -> 41.184775 | O10: =SB_s/3600 -> 0.011440215
A11: Operating Time | B11: OT | C11: AT | D11: Available and under the control of a human OR A SYSTEM. Conventionally gross operating hours (GOH). The 'or a system' wording is what makes the model apply to autonomous fleets. | E11: From leaving the depot to returning to it, including stops for pedestrians and at bus stops. Engaged autonomous driving and manual driving by the safety operator both count. | F11: OT = AT - SB | G11: =AT_s-SB_s -> 2205.8259 | H11: Partial (heuristic) | I11: none directly (inherits SB's fields) | J11: AT, SB | K11: Inherits the depot geofence from SB and the maintenance log from DT. | L11: Identity. In practice OT is everything in the roster that is not SB (and not DT once a log exists). Cross-check: OT should equal the sum of state in {OD, WT, NP} on the Classification sheet (Summary!CHK1 covers this). The events feed, when specified, can refine the boundary: an 'engage' followed by movement marks the start of OT more precisely than the first speed sample. | M11: Under DT = 0, OT = ST - SB, so anything the heuristic misclassifies as SB is lost from OT and vice versa. | N11: =OT_s -> 2205.8259 | O11: =OT_s/3600 -> 0.61272942
A12: Operating Delay | B12: OD | C12: OT | D12: Running but temporarily stopped by delays inherent to the operation or the immediate physical conditions. Within the operator's control conventionally, or the control system's autonomously: waiting for assignment, stuck, spill cleanup with operator aboard, loss of GPS or site wireless, safety stops. | E12: Stopped for a pedestrian or cyclist, obstacle on the path, safety-operator takeover (disengagement) and recovery, GPS/RTK dropout, waiting at a crossing, emergency stop. | F12: OD = OT - WT (measured as stationary away from the depot for >= dwell, GPS loss while stopped, telemetry gaps away from the depot, and disengagement events once available) | G12: =SUMIFS(Classification!$H:$H,Classification!$S:$S,"OD") -> 20.753288 | H12: Partial (heuristic) | I12: timestamp, latitude, longitude, speed_mps, gps_status | J12: OT (and SB, so a stop is not counted twice) | K12: DELAY_DWELL_S (config). Route stop geofences to separate passenger dwell from delay. Disengagement events (schema not yet specified, docs/data-schema.md section 3) with engage/disengage pairs and a cause. | L12: 1. Reuse stationary, in_depot and the run grouping from SB. 2. A run that is stationary AND NOT in_depot AND lasts >= DELAY_DWELL_S is OD. Single stationary samples (< DELAY_DWELL_S) are normal driving: give-way, corners. 3. A stationary sample with gps_status = -1 is OD regardless of run length (GMG names loss of GPS as an operating delay). A moving sample with no fix stays WT. 4. A telemetry gap > MAX_GAP_S whose last sample was away from the depot is OD (loss of site wireless). 5. When events arrive: every interval between a disengage and the next engage is OD via the override column, unless the cause is a fault, in which case it is DT. Events must be joined by vehicle_id and timestamp; if they are timestamped by the receiver rather than the vehicle, align them to the nearest position sample. 6. With a stop list: a stationary run inside a stop geofence and shorter than a max dwell is boarding, i.e. intended function (PT, or NP as 'waiting at the loading unit'), NOT OD. | M12: Without stop geofences every bus-stop dwell >= DELAY_DWELL_S is counted as OD, which overstates delay on a passenger service. In the sample two 10 s roadside stops qualify as OD. | N12: =OD_s -> 20.753288 | O12: =OD_s/3600 -> 0.0057648023
A13: Working Time | B13: WT | C13: OT | D13: Operating as assigned and performing its intended function, covering activities that do and do not directly produce. Conventionally net operating hours (NOH). | E13: Driving the route with or without passengers, boarding at stops, repositioning between runs. | F13: WT = OT - OD | G13: =OT_s-OD_s -> 2185.0726 | H13: Partial (heuristic) | I13: none directly | J13: OT, OD | K13: Inherits everything above it. | L13: Identity. Equivalent to the sum of state in {WT, NP} on the Classification sheet (Summary!CHK3). Because NP cannot be isolated, report at Working Time as the guideline allows; the dashboard's finest honest bucket today is WT. | M13: Inherits every heuristic error from SB and OD. | N13: =WT_s -> 2185.0726 | O13: =WT_s/3600 -> 0.60696462
A14: Non-Productive Time | B14: NP | C14: WT | D14: Unavoidable activity that does not directly produce but enables safe, efficient operation to continue: face cleanup, moving trailing cables, tramming, travel empty, waiting at the loading unit. | E14: Driving the route with zero passengers aboard, deadheading back to the depot or to the start of the route, waiting at a stop for passengers to arrive. | F14: NP = WT - PT (measured from passenger occupancy) | G14: =SUMIFS(Classification!$H:$H,Classification!$S:$S,"NP") -> 0 | H14: No (external data) | I14: none. Needs an occupancy signal per sample or per trip. | J14: WT | K14: Passenger count (door sensor / APC, seat sensors, or a manual tally per trip). Optionally route stop geofences for the 'waiting at loading unit' proxy. | L14: 1. Join occupancy to the position stream: a sample interval with occupancy = 0 while moving, or stationary at a stop with occupancy = 0, is NP (override column). 2. NP_s = SUMIFS over state = NP. Proxy without a count: define the route as a polyline; movement away from the route (to the depot or a charger) is deadheading = NP. Everything on-route stays PT. This under-counts empty runs. | M14: Until occupancy exists, NP = 0 and PT = WT by construction. Label Production Effectiveness as 'PT folded into WT'. | N14: =NP_s -> 0 | O14: =NP_s/3600 -> 0
A15: Productive Time | B15: PT | C15: WT | D15: Performing its intended function on activities that directly contribute to production. If NP cannot be isolated, fold the two together and report at Working Time. | E15: Carrying passengers along the route, including dwell at stops while they board. | F15: PT = WT - NP | G15: =WT_s-NP_s -> 2185.0726 | H15: No (external data) | I15: none directly | J15: WT, NP | K15: Inherits the occupancy requirement from NP. | L15: Identity. Reported as WT until NP is measurable. | M15: Same as NP. | N15: =PT_s -> 2185.0726 | O15: =PT_s/3600 -> 0.60696462

Sheet KPIs
A1: GMG KPIs
A2: Each KPI is a ratio of layer totals. Feasibility is the weakest feasibility of the layers it uses. Any KPI that touches DT is only meaningful once a maintenance log exists.
A4: KPI | B4: Equation | C4: Excel formula | D4: Sample value | E4: Layers used | F4: Feasible with current data? | G4: What it tells you (GMG) | H4: Dashboard note
A5: Uptime | B5: AT / CT | C5: =IFERROR(AT_s/CT_s,0) -> 1 | D5: =IFERROR(AT_s/CT_s,0) -> 1 | E5: AT, CT | F5: Yes (config) | G5: Time the asset was capable of operating, scheduled or not. | H5: Valid only under DT = 0 until a maintenance log exists; then it equals ST / CT, i.e. the roster fraction. Say so on the tile.
A6: Calendar Availability | B6: (CT - DT) / CT | C6: =IFERROR((CT_s-DT_s)/CT_s,0) -> 1 | D6: =IFERROR((CT_s-DT_s)/CT_s,0) -> 1 | E6: CT, DT | F6: No (external data) | G6: Guideline alternative to Uptime that strips the effect of unscheduled time dragging the metric down (often a commercial decision rather than an equipment problem). | H6: Always 100% with DT = 0. Hide until DT is real.
A7: Mechanical Availability | B7: OT / (OT + DT) | C7: =IFERROR(OT_s/(OT_s+DT_s),0) -> 1 | D7: =IFERROR(OT_s/(OT_s+DT_s),0) -> 1 | E7: OT, DT | F7: No (external data) | G7: The cleanest read on maintenance impact. Numerator is operating time, not available time, so standby is excluded and idle hours cannot inflate it. | H7: Always 100% with DT = 0. Hide until DT is real.
A8: Physical Availability | B8: AT / ST | C8: =IFERROR(AT_s/ST_s,0) -> 1 | D8: =IFERROR(AT_s/ST_s,0) -> 1 | E8: AT, ST | F8: No (external data) | G8: Availability that does absorb standby; contrast with Mechanical Availability. | H8: Always 100% with DT = 0. Hide until DT is real.
A9: Use of Availability | B9: OT / AT | C9: =IFERROR(OT_s/AT_s,0) -> 0.9816713 | D9: =IFERROR(OT_s/AT_s,0) -> 0.9816713 | E9: OT, AT | F9: Partial (heuristic) | G9: How well the operation uses the equipment it has in working order. The maintenance-versus-operations dividing line: high mechanical availability with low use of availability means the fleet is fine and the operation is not feeding it work. | H9: Computable today as 1 - SB / ST. Quality depends on the depot geofence and roster.
A10: Asset Utilisation | B10: OT / CT | C10: =IFERROR(OT_s/CT_s,0) -> 0.9816713 | D10: =IFERROR(OT_s/CT_s,0) -> 0.9816713 | E10: OT, CT | F10: Partial (heuristic) | G10: Operating hours against all calendar hours. | H10: Computable today. Small numbers are normal for a daytime-only service (10 h roster => max ~42%).
A11: Effective Utilisation | B11: WT / ST | C11: =IFERROR(WT_s/ST_s,0) -> 0.97243535 | D11: =IFERROR(WT_s/ST_s,0) -> 0.97243535 | E11: WT, ST | F11: Partial (heuristic) | G11: Intended-function time against scheduled time. Clears downtime, standby and operating delay in one ratio: the closest single number to 'did we get value from the shift'. | H11: Computable today; the headline utilisation tile. Needs the roster or ST is 24 h/day.
A12: Operating Efficiency | B12: WT / OT | C12: =IFERROR(WT_s/OT_s,0) -> 0.9905916 | D12: =IFERROR(WT_s/OT_s,0) -> 0.9905916 | E12: WT, OT | F12: Partial (heuristic) | G12: Delay burden once the machine is running. For an autonomous shuttle this is close to a direct readout of how often it stops for obstacles and pedestrians. | H12: Computable today. Will improve markedly once disengagement events and stop geofences separate passenger dwell from delay.
A13: Production Effectiveness | B13: PT / OT | C13: =IFERROR(PT_s/OT_s,0) -> 0.9905916 | D13: =IFERROR(PT_s/OT_s,0) -> 0.9905916 | E13: PT, OT | F13: No (external data) | G13: Productive hours against gross operating hours. | H13: Equals Operating Efficiency while NP = 0. Hide or label 'PT folded into WT' until occupancy exists.

Sheet Fields
A1: Dataset fields and where they exist
A2: Y = present and populated, E = column present but empty, - = column absent. Sources: docs/data-schema.md, the CSV headers, data/README.md.
A4: Field | B4: Type | C4: Meaning | D4: positions_1.csv (real, 5 s) | E4: positions_2.csv (synthetic) | F4: rtkfull-gps-track-full.csv (real, ~0.2 s) | G4: sample-track.csv (synthetic) | H4: events (unspecified) | I4: Used by layers | J4: Notes
A5: vehicle_id | B5: text | C5: Which shuttle. Implied by the file name via config/vehicles.yaml, not a column. | D5: file | E5: file | F5: file | G5: file | H5: ? | I5: all (partition key) | J5: Every layer is computed per vehicle then summed for the fleet.
A6: timestamp | B6: ISO 8601 UTC 'Z' | C6: Sample time, microsecond precision. | D6: Y | E6: Y | F6: Y | G6: Y | H6: ? | I6: CT, UT, SB, OD (dt_s, run lengths, roster test) | J6: Parse formula in Classification!B.
A7: timestamp_unix | B7: integer seconds | C7: Same instant as whole seconds. | D7: Y | E7: - | F7: Y | G7: - | H7: ? | I7: none (redundant) | J7: Do not rely on it: absent from positions_2.csv and it drops the sub-second part.
A8: latitude | B8: real WGS84 | C8: Null when no fix. | D8: Y | E8: Y | F8: Y | G8: Y | H8: - | I8: SB, OD (depot / stop geofence) | J8: Both no-fix rows in the real sample still carry a position (last known).
A9: longitude | B9: real WGS84 | C9: Null when no fix. | D9: Y | E9: Y | F9: Y | G9: Y | H9: - | I9: SB, OD
A10: altitude / altitude_m | B10: real m | C10: Ellipsoidal height. | D10: Y | E10: - | F10: Y | G10: - | H10: - | I10: none | J10: Values around -20 m; not useful for classification.
A11: heading / heading_deg | B11: real deg | C11: Course over ground. | D11: Y | E11: Y | F11: Y | G11: Y | H11: - | I11: none | J11: Could separate 'stopped and turning' but adds nothing over speed.
A12: speed_mps | B12: real m/s | C12: Ground speed. | D12: Y | E12: Y | F12: Y | G12: Y | H12: - | I12: SB, OD (stationary test) | J12: Noise floor at rest 0.05 to 0.12 m/s in the real track; max 1.86 m/s.
A13: gps_status | B13: int | C13: -1 no fix, 0 fix, 1 SBAS, 2 GBAS. | D13: Y | E13: - | F13: Y | G13: - | H13: - | I13: OD (loss of GPS), position trust for SB | J13: Two of 439 real rows are -1. Absent from the synthetic files, so treat missing as 'fix'.
A14: position_covariance_type | B14: int | C14: sensor_msgs/NavSatFix covariance type. | D14: Y | E14: - | F14: Y | G14: - | H14: - | I14: none | J14: Always 2 in the real data. Not in the API model.
A15: battery_percent | B15: real 0-100 | C15: State of charge. | D15: E | E15: Y | F15: E | G15: Y | H15: - | I15: SB (charging confirmation), DT (flat battery) once populated | J15: Only the synthetic files populate it. Do not build logic on it yet.
A16: engage / disengage event | B16: unspecified | C16: Autonomy engaged or handed to the operator. | D16: - | E16: - | F16: - | G16: - | H16: TBD | I16: OD (delay between disengage and engage), DT (if cause = fault) | J16: Schema unknown: see the four client questions in docs/data-schema.md section 3.
A19: Dataset inventory
A20: File | B20: Rows | C20: Provenance | D20: Interval | E20: Span | F20: Notes
A21: data/sample/positions_1.csv | B21: 439 | C21: Real. Copy of GPS_Report/data/rtkfull-gps-track-5s.csv | D21: 5 s | E21: 2025-09-04 08:21:10 to 08:58:37 UTC (37.5 min) | F21: Used for the Classification sheet. Path length 2.63 km, max 554 m from start, ends 2 m from start (a loop from the depot).
A22: data/sample/positions_2.csv | B22: 220 | C22: Synthetic. Vehicle 1 offset ~200 m and decimated | D22: 10 s | E22: same | F22: No gps_status, no timestamp_unix, battery populated. Exists for the multi-vehicle UI, not for metrics.
A23: GPS_Report/data/rtkfull-gps-track-full.csv | B23: 11173 | C23: Real. Full-rate source of the 5 s file | D23: ~0.2 s | E23: same | F23: Same track at 25x the sample rate. Use it to test that the classifier is insensitive to polling rate.
A24: GPS_Report/data/sample-track.csv | B24: 12 | C24: Synthetic hand-written example | D24: 5 s | E24: 2026-08-17 04:00 UTC, 1 min | F24: Whole-second timestamps (no fraction); the parse formula handles that.
A25: events | B25: 0 | C25: Not delivered | D25: - | E25: - | F25: Format unknown.

Sheet Future inputs
A1: Inputs that would unlock the remaining layers
A3: Input | B3: What it is | C3: Suggested format / home | D3: Unlocks | E3: Effect on feasibility | F3: Priority
A4: Service roster | B4: Daily start/end per weekday, plus holiday and non-service dates. | C4: config/app.yaml service_hours block, or a small table (weekday, start, end) and (date, reason). | D4: UT, ST and every KPI with ST or CT in the denominator | E4: Turns UT/ST from placeholder to Yes. Without it ST = CT and utilisation looks tiny. | F4: 1
A5: Depot geofence | B5: Centre and radius of where the shuttle parks between runs. | C5: config/app.yaml (map.centre is already the right point); DEPOT_* parameters here. | D5: SB, hence OT | E5: Confirms the standby heuristic. Add a second fence if there is a charging bay elsewhere. | F5: 1
A6: Route stop list | B6: Lat/lon/radius of each passenger stop on the nUWAy route. | C6: Table (stop_id, name, lat, lon, radius_m) in config or the database. | D6: OD vs PT/NP split | E6: Stops passenger boarding being counted as Operating Delay. Biggest accuracy win for Operating Efficiency. | F6: 2
A7: Disengagement events | B7: Engage/disengage records with cause, per docs/data-schema.md section 3. | C7: events table (vehicle_id, timestamp, kind, cause) once the client answers the four open questions. | D7: OD (precise), DT (fault cause) | E7: Replaces the 'stationary away from depot' proxy with ground truth for takeovers. | F7: 2
A8: Maintenance / fault log | B8: Periods the vehicle was not fit for duty, with cause. | C8: CMMS export or a manual sheet (vehicle_id, start, end, cause). | D8: DT, AT, all availability KPIs | E8: Only way to make Uptime, Mechanical and Physical Availability meaningful. | F8: 2
A9: Passenger occupancy | B9: Number aboard per sample or per trip. | C9: Door-counter feed joined by timestamp, or a per-trip tally. | D9: NP, PT, Production Effectiveness | E9: Lets PT be split from WT as the guideline intends. | F9: 3
A10: Standby reason codes | B10: Why the shuttle was parked: operator break, no operator, weather, closure. | C10: Operator log or roster exceptions. | D10: SBO / SBE split | E10: Needed for contractor-style billing of external standby. | F10: 3
A11: Real battery telemetry | B11: battery_percent populated by the live feed. | C11: Already in the schema; needs the vehicle to publish it. | D11: SB confirmation, DT (flat) | E11: Nice to have. | F11: 3

Sheet Parameters
A1: Tunable parameters
A2: Every classification formula reads these named cells. Change a value here and the Classification, Summary, Layers and KPIs sheets recalculate. All are placeholders to be confirmed with the client unless the Source column says otherwise.
A4: Name | B4: Value | C4: Unit | D4: Description | E4: Source / justification
A5: SPEED_STOP_MPS | B5: 0.2 | C5: m/s | D5: Speed at or below which a sample counts as stationary. Real track shows GPS speed noise of 0.05 to 0.12 m/s while parked, so 0.1 is too tight; 0.2 leaves margin. | E5: Measured from positions_1.csv (real).
A6: DEPOT_LAT | B6: -31.98133 | C6: deg WGS84 | D6: Latitude of the depot / base geofence centre. Standby is only counted inside this fence. | E6: First sample of the real track, which is also the map centre in config/app.yaml. Confirm with client.
A7: DEPOT_LON | B7: 115.81597 | C7: deg WGS84 | D7: Longitude of the depot geofence centre. | E7: As above.
A8: DEPOT_RADIUS_M | B8: 30 | C8: m | D8: Radius of the depot geofence. RTK fix error is sub-metre; a plain fix can wander ~5 m, so 30 m keeps a parked shuttle inside the fence without swallowing the adjacent road. | E8: Placeholder.
A9: STANDBY_DWELL_S | B9: 30 | C9: s | D9: A stationary run inside the depot must last at least this long before it is Standby. Shorter stops in the depot are treated as Working Time (about to depart / just arrived). | E9: Placeholder. Client to advise typical layover.
A10: DELAY_DWELL_S | B10: 10 | C10: s | D10: A stationary run away from the depot must last at least this long before it is an Operating Delay. At 5 s polling this is two consecutive stationary samples; a single stationary sample is treated as normal driving (give-way, corner). | E10: Placeholder. Two polling intervals at expected_poll_interval_seconds=6 in config/app.yaml.
A11: MAX_GAP_S | B11: 300 | C11: s | D11: A gap between consecutive samples longer than this is a telemetry outage. The interval is still attributed (Standby if last seen inside the depot, else Operating Delay) so all Calendar Time is accounted for. | E11: config/app.yaml liveness.inactivity_threshold_seconds.
A12: SERVICE_START | B12: 0.33333333 | C12: time of day (Perth) | D12: Start of the daily service window. Time outside the window on service days, and all of non-service days, is Unscheduled Time. | E12: Placeholder. Needs the nUWAy roster from the client.
A13: SERVICE_END | B13: 0.75 | C13: time of day (Perth) | D13: End of the daily service window. | E13: Placeholder.
A14: SERVICE_LAST_WEEKDAY | B14: 5 | C14: 1=Mon .. 7=Sun | D14: Last day of the week that is a service day. 5 means Monday to Friday. | E14: Placeholder.
A15: UTC_OFFSET_H | B15: 8 | C15: h | D15: Offset applied to the stored UTC timestamps before testing the service window. Perth is UTC+8 year round. | E15: docs/data-schema.md section 4 and config/app.yaml display.utc_offset_hours.
A16: WINDOW_START | C16: UTC datetime | D16: Optional. Start of the reporting window. Leave blank to use the first sample. Set both WINDOW_* cells to report a full day or week so that time with no telemetry is counted as Calendar Time rather than silently dropped. | E16: Equivalent to the from parameter of GET /api/positions.
A17: WINDOW_END | C17: UTC datetime | D17: Optional. End of the reporting window. Leave blank to use the last sample. | E17: Equivalent to the to parameter of GET /api/positions.

Sheet Classification
A1: timestamp (dataset) | B1: t_utc | C1: t_local | D1: latitude | E1: longitude | F1: speed_mps | G1: gps_status | H1: dt_s | I1: dist_depot_m | J1: in_service | K1: stationary | L1: in_depot | M1: has_fix | N1: gap | O1: run_id | P1: run_s | Q1: state_auto | R1: override | S1: state | U1: Column notes
A2: 2025-09-04T08:21:10.484987Z | B2: =DATE(VALUE(LEFT(A2,4)),VALUE(MID(A2,6,2)),VALUE(MID(A2,9,2)))+TIME(VALUE(MID(A2,12,2)),VALUE(MID(A2,15,2)),VALUE(MID(A2,18,2)))+IFERROR(VALUE(MID(A2,21,6)),0)/86400000000 -> 45904.348 | C2: =B2+UTC_OFFSET_H/24 -> 45904.681 | D2: -31.981331 | E2: 115.81597 | F2: 0 | G2: 0 | H2: =(B3-B2)*86400 -> 5.0071073 | I2: =2*6371000*ASIN(SQRT(SIN((RADIANS(D2)-RADIANS(DEPOT_LAT))/2)^2+COS(RADIANS(DEPOT_LAT))*COS(RADIANS(D2))*SIN((RADIANS(E2)-RADIANS(DEPOT_LON))/2)^2)) -> 0.22531148 | J2: =AND(WEEKDAY(C2,2)<=SERVICE_LAST_WEEKDAY,MOD(C2,1)>=SERVICE_START,MOD(C2,1)<SERVICE_END) -> TRUE | K2: =F2<SPEED_STOP_MPS -> TRUE | L2: =I2<=DEPOT_RADIUS_M -> TRUE | M2: =G2>=0 -> TRUE | N2: =H2>MAX_GAP_S -> FALSE | O2: 1 | P2: =SUMIFS($H$2:$H$440,$O$2:$O$440,O2) -> 41.184775 | Q2: =IF(NOT(J2),"UT",IF(N2,IF(L2,"SB","OD"),IF(AND(K2,L2,P2>=STANDBY_DWELL_S),"SB",IF(AND(K2,NOT(M2)),"OD",IF(AND(K2,NOT(L2),P2>=DELAY_DWELL_S),"OD","WT"))))) -> SB | S2: =IF(R2<>"",R2,Q2) -> SB | U2: t_utc | V2: Parse ISO 8601 text to an Excel datetime (UTC).
A3: 2025-09-04T08:21:15.492094Z | B3: =DATE(VALUE(LEFT(A3,4)),VALUE(MID(A3,6,2)),VALUE(MID(A3,9,2)))+TIME(VALUE(MID(A3,12,2)),VALUE(MID(A3,15,2)),VALUE(MID(A3,18,2)))+IFERROR(VALUE(MID(A3,21,6)),0)/86400000000 -> 45904.348 | C3: =B3+UTC_OFFSET_H/24 -> 45904.681 | D3: -31.981328 | E3: 115.81598 | F3: 0.12 | G3: 0 | H3: =(B4-B3)*86400 -> 5.1935942 | I3: =2*6371000*ASIN(SQRT(SIN((RADIANS(D3)-RADIANS(DEPOT_LAT))/2)^2+COS(RADIANS(DEPOT_LAT))*COS(RADIANS(D3))*SIN((RADIANS(E3)-RADIANS(DEPOT_LON))/2)^2)) -> 0.71673393 | J3: =AND(WEEKDAY(C3,2)<=SERVICE_LAST_WEEKDAY,MOD(C3,1)>=SERVICE_START,MOD(C3,1)<SERVICE_END) -> TRUE | K3: =F3<SPEED_STOP_MPS -> TRUE | L3: =I3<=DEPOT_RADIUS_M -> TRUE | M3: =G3>=0 -> TRUE | N3: =H3>MAX_GAP_S -> FALSE | O3: =IF(AND(K3=K2,L3=L2),O2,O2+1) -> 1 | P3: =SUMIFS($H$2:$H$440,$O$2:$O$440,O3) -> 41.184775 | Q3: =IF(NOT(J3),"UT",IF(N3,IF(L3,"SB","OD"),IF(AND(K3,L3,P3>=STANDBY_DWELL_S),"SB",IF(AND(K3,NOT(M3)),"OD",IF(AND(K3,NOT(L3),P3>=DELAY_DWELL_S),"OD","WT"))))) -> SB | S3: =IF(R3<>"",R3,Q3) -> SB | U3: t_local | V3: Shift to Perth for the service-window test.
A4: 2025-09-04T08:21:20.685688Z | B4: =DATE(VALUE(LEFT(A4,4)),VALUE(MID(A4,6,2)),VALUE(MID(A4,9,2)))+TIME(VALUE(MID(A4,12,2)),VALUE(MID(A4,15,2)),VALUE(MID(A4,18,2)))+IFERROR(VALUE(MID(A4,21,6)),0)/86400000000 -> 45904.348 | C4: =B4+UTC_OFFSET_H/24 -> 45904.681 | D4: -31.981325 | E4: 115.81598 | F4: 0.118 | G4: 0 | H4: =(B5-B4)*86400 -> 5.0060299 | I4: =2*6371000*ASIN(SQRT(SIN((RADIANS(D4)-RADIANS(DEPOT_LAT))/2)^2+COS(RADIANS(DEPOT_LAT))*COS(RADIANS(D4))*SIN((RADIANS(E4)-RADIANS(DEPOT_LON))/2)^2)) -> 1.3223296 | J4: =AND(WEEKDAY(C4,2)<=SERVICE_LAST_WEEKDAY,MOD(C4,1)>=SERVICE_START,MOD(C4,1)<SERVICE_END) -> TRUE | K4: =F4<SPEED_STOP_MPS -> TRUE | L4: =I4<=DEPOT_RADIUS_M -> TRUE | M4: =G4>=0 -> TRUE | N4: =H4>MAX_GAP_S -> FALSE | O4: =IF(AND(K4=K3,L4=L3),O3,O3+1) -> 1 | P4: =SUMIFS($H$2:$H$440,$O$2:$O$440,O4) -> 41.184775 | Q4: =IF(NOT(J4),"UT",IF(N4,IF(L4,"SB","OD"),IF(AND(K4,L4,P4>=STANDBY_DWELL_S),"SB",IF(AND(K4,NOT(M4)),"OD",IF(AND(K4,NOT(L4),P4>=DELAY_DWELL_S),"OD","WT"))))) -> SB | S4: =IF(R4<>"",R4,Q4) -> SB | U4: dt_s | V4: Seconds until the next sample. This interval is what gets classified.
A5: 2025-09-04T08:21:25.691718Z | B5: =DATE(VALUE(LEFT(A5,4)),VALUE(MID(A5,6,2)),VALUE(MID(A5,9,2)))+TIME(VALUE(MID(A5,12,2)),VALUE(MID(A5,15,2)),VALUE(MID(A5,18,2)))+IFERROR(VALUE(MID(A5,21,6)),0)/86400000000 -> 45904.348 | C5: =B5+UTC_OFFSET_H/24 -> 45904.682 | D5: -31.981322 | E5: 115.81599 | F5: 0.092 | G5: 0 | H5: =(B6-B5)*86400 -> 5.1901386 | I5: =2*6371000*ASIN(SQRT(SIN((RADIANS(D5)-RADIANS(DEPOT_LAT))/2)^2+COS(RADIANS(DEPOT_LAT))*COS(RADIANS(D5))*SIN((RADIANS(E5)-RADIANS(DEPOT_LON))/2)^2)) -> 1.7634849 | J5: =AND(WEEKDAY(C5,2)<=SERVICE_LAST_WEEKDAY,MOD(C5,1)>=SERVICE_START,MOD(C5,1)<SERVICE_END) -> TRUE | K5: =F5<SPEED_STOP_MPS -> TRUE | L5: =I5<=DEPOT_RADIUS_M -> TRUE | M5: =G5>=0 -> TRUE | N5: =H5>MAX_GAP_S -> FALSE | O5: =IF(AND(K5=K4,L5=L4),O4,O4+1) -> 1 | P5: =SUMIFS($H$2:$H$440,$O$2:$O$440,O5) -> 41.184775 | Q5: =IF(NOT(J5),"UT",IF(N5,IF(L5,"SB","OD"),IF(AND(K5,L5,P5>=STANDBY_DWELL_S),"SB",IF(AND(K5,NOT(M5)),"OD",IF(AND(K5,NOT(L5),P5>=DELAY_DWELL_S),"OD","WT"))))) -> SB | S5: =IF(R5<>"",R5,Q5) -> SB | U5: dist_depot_m | V5: Haversine distance to the depot geofence centre.
A6: 2025-09-04T08:21:30.881857Z | B6: =DATE(VALUE(LEFT(A6,4)),VALUE(MID(A6,6,2)),VALUE(MID(A6,9,2)))+TIME(VALUE(MID(A6,12,2)),VALUE(MID(A6,15,2)),VALUE(MID(A6,18,2)))+IFERROR(VALUE(MID(A6,21,6)),0)/86400000000 -> 45904.348 | C6: =B6+UTC_OFFSET_H/24 -> 45904.682 | D6: -31.98132 | E6: 115.81599 | F6: 0.085 | G6: 0 | H6: =(B7-B6)*86400 -> 5.1932384 | I6: =2*6371000*ASIN(SQRT(SIN((RADIANS(D6)-RADIANS(DEPOT_LAT))/2)^2+COS(RADIANS(DEPOT_LAT))*COS(RADIANS(D6))*SIN((RADIANS(E6)-RADIANS(DEPOT_LON))/2)^2)) -> 2.1841317 | J6: =AND(WEEKDAY(C6,2)<=SERVICE_LAST_WEEKDAY,MOD(C6,1)>=SERVICE_START,MOD(C6,1)<SERVICE_END) -> TRUE | K6: =F6<SPEED_STOP_MPS -> TRUE | L6: =I6<=DEPOT_RADIUS_M -> TRUE | M6: =G6>=0 -> TRUE | N6: =H6>MAX_GAP_S -> FALSE | O6: =IF(AND(K6=K5,L6=L5),O5,O5+1) -> 1 | P6: =SUMIFS($H$2:$H$440,$O$2:$O$440,O6) -> 41.184775 | Q6: =IF(NOT(J6),"UT",IF(N6,IF(L6,"SB","OD"),IF(AND(K6,L6,P6>=STANDBY_DWELL_S),"SB",IF(AND(K6,NOT(M6)),"OD",IF(AND(K6,NOT(L6),P6>=DELAY_DWELL_S),"OD","WT"))))) -> SB | S6: =IF(R6<>"",R6,Q6) -> SB | U6: in_service | V6: Inside roster? Otherwise the interval is Unscheduled.
A7: 2025-09-04T08:21:36.075095Z | B7: =DATE(VALUE(LEFT(A7,4)),VALUE(MID(A7,6,2)),VALUE(MID(A7,9,2)))+TIME(VALUE(MID(A7,12,2)),VALUE(MID(A7,15,2)),VALUE(MID(A7,18,2)))+IFERROR(VALUE(MID(A7,21,6)),0)/86400000000 -> 45904.348 | C7: =B7+UTC_OFFSET_H/24 -> 45904.682 | D7: -31.981318 | E7: 115.81599 | F7: 0.061 | G7: 0 | H7: =(B8-B7)*86400 -> 5.2206849 | I7: =2*6371000*ASIN(SQRT(SIN((RADIANS(D7)-RADIANS(DEPOT_LAT))/2)^2+COS(RADIANS(DEPOT_LAT))*COS(RADIANS(D7))*SIN((RADIANS(E7)-RADIANS(DEPOT_LON))/2)^2)) -> 2.5011254 | J7: =AND(WEEKDAY(C7,2)<=SERVICE_LAST_WEEKDAY,MOD(C7,1)>=SERVICE_START,MOD(C7,1)<SERVICE_END) -> TRUE | K7: =F7<SPEED_STOP_MPS -> TRUE | L7: =I7<=DEPOT_RADIUS_M -> TRUE | M7: =G7>=0 -> TRUE | N7: =H7>MAX_GAP_S -> FALSE | O7: =IF(AND(K7=K6,L7=L6),O6,O6+1) -> 1 | P7: =SUMIFS($H$2:$H$440,$O$2:$O$440,O7) -> 41.184775 | Q7: =IF(NOT(J7),"UT",IF(N7,IF(L7,"SB","OD"),IF(AND(K7,L7,P7>=STANDBY_DWELL_S),"SB",IF(AND(K7,NOT(M7)),"OD",IF(AND(K7,NOT(L7),P7>=DELAY_DWELL_S),"OD","WT"))))) -> SB | S7: =IF(R7<>"",R7,Q7) -> SB | U7: stationary | V7: speed_mps below SPEED_STOP_MPS.
A8: 2025-09-04T08:21:41.295780Z | B8: =DATE(VALUE(LEFT(A8,4)),VALUE(MID(A8,6,2)),VALUE(MID(A8,9,2)))+TIME(VALUE(MID(A8,12,2)),VALUE(MID(A8,15,2)),VALUE(MID(A8,18,2)))+IFERROR(VALUE(MID(A8,21,6)),0)/86400000000 -> 45904.348 | C8: =B8+UTC_OFFSET_H/24 -> 45904.682 | D8: -31.981316 | E8: 115.81599 | F8: 0.062 | G8: 0 | H8: =(B9-B8)*86400 -> 5.1904089 | I8: =2*6371000*ASIN(SQRT(SIN((RADIANS(D8)-RADIANS(DEPOT_LAT))/2)^2+COS(RADIANS(DEPOT_LAT))*COS(RADIANS(D8))*SIN((RADIANS(E8)-RADIANS(DEPOT_LON))/2)^2)) -> 2.8206965 | J8: =AND(WEEKDAY(C8,2)<=SERVICE_LAST_WEEKDAY,MOD(C8,1)>=SERVICE_START,MOD(C8,1)<SERVICE_END) -> TRUE | K8: =F8<SPEED_STOP_MPS -> TRUE | L8: =I8<=DEPOT_RADIUS_M -> TRUE | M8: =G8>=0 -> TRUE | N8: =H8>MAX_GAP_S -> FALSE | O8: =IF(AND(K8=K7,L8=L7),O7,O7+1) -> 1 | P8: =SUMIFS($H$2:$H$440,$O$2:$O$440,O8) -> 41.184775 | Q8: =IF(NOT(J8),"UT",IF(N8,IF(L8,"SB","OD"),IF(AND(K8,L8,P8>=STANDBY_DWELL_S),"SB",IF(AND(K8,NOT(M8)),"OD",IF(AND(K8,NOT(L8),P8>=DELAY_DWELL_S),"OD","WT"))))) -> SB | S8: =IF(R8<>"",R8,Q8) -> SB | U8: in_depot | V8: dist_depot_m within DEPOT_RADIUS_M.
A9: 2025-09-04T08:21:46.486189Z | B9: =DATE(VALUE(LEFT(A9,4)),VALUE(MID(A9,6,2)),VALUE(MID(A9,9,2)))+TIME(VALUE(MID(A9,12,2)),VALUE(MID(A9,15,2)),VALUE(MID(A9,18,2)))+IFERROR(VALUE(MID(A9,21,6)),0)/86400000000 -> 45904.348 | C9: =B9+UTC_OFFSET_H/24 -> 45904.682 | D9: -31.981316 | E9: 115.816 | F9: 0.144 | G9: 0 | H9: =(B10-B9)*86400 -> 5.183573 | I9: =2*6371000*ASIN(SQRT(SIN((RADIANS(D9)-RADIANS(DEPOT_LAT))/2)^2+COS(RADIANS(DEPOT_LAT))*COS(RADIANS(D9))*SIN((RADIANS(E9)-RADIANS(DEPOT_LON))/2)^2)) -> 3.4584315 | J9: =AND(WEEKDAY(C9,2)<=SERVICE_LAST_WEEKDAY,MOD(C9,1)>=SERVICE_START,MOD(C9,1)<SERVICE_END) -> TRUE | K9: =F9<SPEED_STOP_MPS -> TRUE | L9: =I9<=DEPOT_RADIUS_M -> TRUE | M9: =G9>=0 -> TRUE | N9: =H9>MAX_GAP_S -> FALSE | O9: =IF(AND(K9=K8,L9=L8),O8,O8+1) -> 1 | P9: =SUMIFS($H$2:$H$440,$O$2:$O$440,O9) -> 41.184775 | Q9: =IF(NOT(J9),"UT",IF(N9,IF(L9,"SB","OD"),IF(AND(K9,L9,P9>=STANDBY_DWELL_S),"SB",IF(AND(K9,NOT(M9)),"OD",IF(AND(K9,NOT(L9),P9>=DELAY_DWELL_S),"OD","WT"))))) -> SB | S9: =IF(R9<>"",R9,Q9) -> SB | U9: has_fix | V9: gps_status >= 0 (-1 is no fix).
A10: 2025-09-04T08:21:51.669762Z | B10: =DATE(VALUE(LEFT(A10,4)),VALUE(MID(A10,6,2)),VALUE(MID(A10,9,2)))+TIME(VALUE(MID(A10,12,2)),VALUE(MID(A10,15,2)),VALUE(MID(A10,18,2)))+IFERROR(VALUE(MID(A10,21,6)),0)/86400000000 -> 45904.349 | C10: =B10+UTC_OFFSET_H/24 -> 45904.682 | D10: -31.981318 | E10: 115.81606 | F10: 1.065 | G10: 0 | H10: =(B11-B10)*86400 -> 5.0057759 | I10: =2*6371000*ASIN(SQRT(SIN((RADIANS(D10)-RADIANS(DEPOT_LAT))/2)^2+COS(RADIANS(DEPOT_LAT))*COS(RADIANS(D10))*SIN((RADIANS(E10)-RADIANS(DEPOT_LON))/2)^2)) -> 8.7096795 | J10: =AND(WEEKDAY(C10,2)<=SERVICE_LAST_WEEKDAY,MOD(C10,1)>=SERVICE_START,MOD(C10,1)<SERVICE_END) -> TRUE | K10: =F10<SPEED_STOP_MPS -> FALSE | L10: =I10<=DEPOT_RADIUS_M -> TRUE | M10: =G10>=0 -> TRUE | N10: =H10>MAX_GAP_S -> FALSE | O10: =IF(AND(K10=K9,L10=L9),O9,O9+1) -> 2 | P10: =SUMIFS($H$2:$H$440,$O$2:$O$440,O10) -> 20.619093 | Q10: =IF(NOT(J10),"UT",IF(N10,IF(L10,"SB","OD"),IF(AND(K10,L10,P10>=STANDBY_DWELL_S),"SB",IF(AND(K10,NOT(M10)),"OD",IF(AND(K10,NOT(L10),P10>=DELAY_DWELL_S),"OD","WT"))))) -> WT | S10: =IF(R10<>"",R10,Q10) -> WT | U10: gap | V10: dt_s above MAX_GAP_S: telemetry outage.
A11: 2025-09-04T08:21:56.675538Z | B11: =DATE(VALUE(LEFT(A11,4)),VALUE(MID(A11,6,2)),VALUE(MID(A11,9,2)))+TIME(VALUE(MID(A11,12,2)),VALUE(MID(A11,15,2)),VALUE(MID(A11,18,2)))+IFERROR(VALUE(MID(A11,21,6)),0)/86400000000 -> 45904.349 | C11: =B11+UTC_OFFSET_H/24 -> 45904.682 | D11: -31.981316 | E11: 115.81613 | F11: 1.245 | G11: 0 | H11: =(B12-B11)*86400 -> 5.2014164 | I11: =2*6371000*ASIN(SQRT(SIN((RADIANS(D11)-RADIANS(DEPOT_LAT))/2)^2+COS(RADIANS(DEPOT_LAT))*COS(RADIANS(D11))*SIN((RADIANS(E11)-RADIANS(DEPOT_LON))/2)^2)) -> 14.911181 | J11: =AND(WEEKDAY(C11,2)<=SERVICE_LAST_WEEKDAY,MOD(C11,1)>=SERVICE_START,MOD(C11,1)<SERVICE_END) -> TRUE | K11: =F11<SPEED_STOP_MPS -> FALSE | L11: =I11<=DEPOT_RADIUS_M -> TRUE | M11: =G11>=0 -> TRUE | N11: =H11>MAX_GAP_S -> FALSE | O11: =IF(AND(K11=K10,L11=L10),O10,O10+1) -> 2 | P11: =SUMIFS($H$2:$H$440,$O$2:$O$440,O11) -> 20.619093 | Q11: =IF(NOT(J11),"UT",IF(N11,IF(L11,"SB","OD"),IF(AND(K11,L11,P11>=STANDBY_DWELL_S),"SB",IF(AND(K11,NOT(M11)),"OD",IF(AND(K11,NOT(L11),P11>=DELAY_DWELL_S),"OD","WT"))))) -> WT | S11: =IF(R11<>"",R11,Q11) -> WT | U11: run_id | V11: Increments when stationary or in_depot changes, so a run is a maximal stretch with the same status.
A12: 2025-09-04T08:22:01.876955Z | B12: =DATE(VALUE(LEFT(A12,4)),VALUE(MID(A12,6,2)),VALUE(MID(A12,9,2)))+TIME(VALUE(MID(A12,12,2)),VALUE(MID(A12,15,2)),VALUE(MID(A12,18,2)))+IFERROR(VALUE(MID(A12,21,6)),0)/86400000000 -> 45904.349 | C12: =B12+UTC_OFFSET_H/24 -> 45904.682 | D12: -31.981312 | E12: 115.81619 | F12: 1.184 | G12: 0 | H12: =(B13-B12)*86400 -> 5.1892075 | I12: =2*6371000*ASIN(SQRT(SIN((RADIANS(D12)-RADIANS(DEPOT_LAT))/2)^2+COS(RADIANS(DEPOT_LAT))*COS(RADIANS(D12))*SIN((RADIANS(E12)-RADIANS(DEPOT_LON))/2)^2)) -> 21.066848 | J12: =AND(WEEKDAY(C12,2)<=SERVICE_LAST_WEEKDAY,MOD(C12,1)>=SERVICE_START,MOD(C12,1)<SERVICE_END) -> TRUE | K12: =F12<SPEED_STOP_MPS -> FALSE | L12: =I12<=DEPOT_RADIUS_M -> TRUE | M12: =G12>=0 -> TRUE | N12: =H12>MAX_GAP_S -> FALSE | O12: =IF(AND(K12=K11,L12=L11),O11,O11+1) -> 2 | P12: =SUMIFS($H$2:$H$440,$O$2:$O$440,O12) -> 20.619093 | Q12: =IF(NOT(J12),"UT",IF(N12,IF(L12,"SB","OD"),IF(AND(K12,L12,P12>=STANDBY_DWELL_S),"SB",IF(AND(K12,NOT(M12)),"OD",IF(AND(K12,NOT(L12),P12>=DELAY_DWELL_S),"OD","WT"))))) -> WT | S12: =IF(R12<>"",R12,Q12) -> WT | U12: run_s | V12: Total length of the run this row belongs to (applies the dwell test to every row of the run, not just the tail).
A13: 2025-09-04T08:22:07.066162Z | B13: =DATE(VALUE(LEFT(A13,4)),VALUE(MID(A13,6,2)),VALUE(MID(A13,9,2)))+TIME(VALUE(MID(A13,12,2)),VALUE(MID(A13,15,2)),VALUE(MID(A13,18,2)))+IFERROR(VALUE(MID(A13,21,6)),0)/86400000000 -> 45904.349 | C13: =B13+UTC_OFFSET_H/24 -> 45904.682 | D13: -31.981308 | E13: 115.81626 | F13: 1.227 | G13: 0 | H13: =(B14-B13)*86400 -> 5.2226928 | I13: =2*6371000*ASIN(SQRT(SIN((RADIANS(D13)-RADIANS(DEPOT_LAT))/2)^2+COS(RADIANS(DEPOT_LAT))*COS(RADIANS(D13))*SIN((RADIANS(E13)-RADIANS(DEPOT_LON))/2)^2)) -> 27.429684 | J13: =AND(WEEKDAY(C13,2)<=SERVICE_LAST_WEEKDAY,MOD(C13,1)>=SERVICE_START,MOD(C13,1)<SERVICE_END) -> TRUE | K13: =F13<SPEED_STOP_MPS -> FALSE | L13: =I13<=DEPOT_RADIUS_M -> TRUE | M13: =G13>=0 -> TRUE | N13: =H13>MAX_GAP_S -> FALSE | O13: =IF(AND(K13=K12,L13=L12),O12,O12+1) -> 2 | P13: =SUMIFS($H$2:$H$440,$O$2:$O$440,O13) -> 20.619093 | Q13: =IF(NOT(J13),"UT",IF(N13,IF(L13,"SB","OD"),IF(AND(K13,L13,P13>=STANDBY_DWELL_S),"SB",IF(AND(K13,NOT(M13)),"OD",IF(AND(K13,NOT(L13),P13>=DELAY_DWELL_S),"OD","WT"))))) -> WT | S13: =IF(R13<>"",R13,Q13) -> WT | U13: state_auto | V13: Leaf bucket from the rules. UT, SB, OD or WT.
A14: 2025-09-04T08:22:12.288855Z | B14: =DATE(VALUE(LEFT(A14,4)),VALUE(MID(A14,6,2)),VALUE(MID(A14,9,2)))+TIME(VALUE(MID(A14,12,2)),VALUE(MID(A14,15,2)),VALUE(MID(A14,18,2)))+IFERROR(VALUE(MID(A14,21,6)),0)/86400000000 -> 45904.349 | C14: =B14+UTC_OFFSET_H/24 -> 45904.682 | D14: -31.981308 | E14: 115.81633 | F14: 1.219 | G14: 0 | H14: =(B15-B14)*86400 -> 5.2017835 | I14: =2*6371000*ASIN(SQRT(SIN((RADIANS(D14)-RADIANS(DEPOT_LAT))/2)^2+COS(RADIANS(DEPOT_LAT))*COS(RADIANS(D14))*SIN((RADIANS(E14)-RADIANS(DEPOT_LON))/2)^2)) -> 33.772294 | J14: =AND(WEEKDAY(C14,2)<=SERVICE_LAST_WEEKDAY,MOD(C14,1)>=SERVICE_START,MOD(C14,1)<SERVICE_END) -> TRUE | K14: =F14<SPEED_STOP_MPS -> FALSE | L14: =I14<=DEPOT_RADIUS_M -> FALSE | M14: =G14>=0 -> TRUE | N14: =H14>MAX_GAP_S -> FALSE | O14: =IF(AND(K14=K13,L14=L13),O13,O13+1) -> 3 | P14: =SUMIFS($H$2:$H$440,$O$2:$O$440,O14) -> 71.5831 | Q14: =IF(NOT(J14),"UT",IF(N14,IF(L14,"SB","OD"),IF(AND(K14,L14,P14>=STANDBY_DWELL_S),"SB",IF(AND(K14,NOT(M14)),"OD",IF(AND(K14,NOT(L14),P14>=DELAY_DWELL_S),"OD","WT"))))) -> WT | S14: =IF(R14<>"",R14,Q14) -> WT | U14: override | V14: Manual or joined value (DT from a maintenance log, NP from a passenger count, OD from a disengagement event). Wins over state_auto.
A15: 2025-09-04T08:22:17.490638Z | B15: =DATE(VALUE(LEFT(A15,4)),VALUE(MID(A15,6,2)),VALUE(MID(A15,9,2)))+TIME(VALUE(MID(A15,12,2)),VALUE(MID(A15,15,2)),VALUE(MID(A15,18,2)))+IFERROR(VALUE(MID(A15,21,6)),0)/86400000000 -> 45904.349 | C15: =B15+UTC_OFFSET_H/24 -> 45904.682 | D15: -31.981311 | E15: 115.8164 | F15: 1.284 | G15: 0 | H15: =(B16-B15)*86400 -> 5.1805291 | I15: =2*6371000*ASIN(SQRT(SIN((RADIANS(D15)-RADIANS(DEPOT_LAT))/2)^2+COS(RADIANS(DEPOT_LAT))*COS(RADIANS(D15))*SIN((RADIANS(E15)-RADIANS(DEPOT_LON))/2)^2)) -> 40.412824 | J15: =AND(WEEKDAY(C15,2)<=SERVICE_LAST_WEEKDAY,MOD(C15,1)>=SERVICE_START,MOD(C15,1)<SERVICE_END) -> TRUE | K15: =F15<SPEED_STOP_MPS -> FALSE | L15: =I15<=DEPOT_RADIUS_M -> FALSE | M15: =G15>=0 -> TRUE | N15: =H15>MAX_GAP_S -> FALSE | O15: =IF(AND(K15=K14,L15=L14),O14,O14+1) -> 3 | P15: =SUMIFS($H$2:$H$440,$O$2:$O$440,O15) -> 71.5831 | Q15: =IF(NOT(J15),"UT",IF(N15,IF(L15,"SB","OD"),IF(AND(K15,L15,P15>=STANDBY_DWELL_S),"SB",IF(AND(K15,NOT(M15)),"OD",IF(AND(K15,NOT(L15),P15>=DELAY_DWELL_S),"OD","WT"))))) -> WT | S15: =IF(R15<>"",R15,Q15) -> WT | U15: state | V15: Final leaf bucket used by Summary.
A16: 2025-09-04T08:22:22.671167Z | B16: =DATE(VALUE(LEFT(A16,4)),VALUE(MID(A16,6,2)),VALUE(MID(A16,9,2)))+TIME(VALUE(MID(A16,12,2)),VALUE(MID(A16,15,2)),VALUE(MID(A16,18,2)))+IFERROR(VALUE(MID(A16,21,6)),0)/86400000000 -> 45904.349 | C16: =B16+UTC_OFFSET_H/24 -> 45904.682 | D16: -31.981308 | E16: 115.81646 | F16: 1.192 | G16: 0 | H16: =(B17-B16)*86400 -> 5.0180998 | I16: =2*6371000*ASIN(SQRT(SIN((RADIANS(D16)-RADIANS(DEPOT_LAT))/2)^2+COS(RADIANS(DEPOT_LAT))*COS(RADIANS(D16))*SIN((RADIANS(E16)-RADIANS(DEPOT_LON))/2)^2)) -> 46.589953 | J16: =AND(WEEKDAY(C16,2)<=SERVICE_LAST_WEEKDAY,MOD(C16,1)>=SERVICE_START,MOD(C16,1)<SERVICE_END) -> TRUE | K16: =F16<SPEED_STOP_MPS -> FALSE | L16: =I16<=DEPOT_RADIUS_M -> FALSE | M16: =G16>=0 -> TRUE | N16: =H16>MAX_GAP_S -> FALSE | O16: =IF(AND(K16=K15,L16=L15),O15,O15+1) -> 3 | P16: =SUMIFS($H$2:$H$440,$O$2:$O$440,O16) -> 71.5831 | Q16: =IF(NOT(J16),"UT",IF(N16,IF(L16,"SB","OD"),IF(AND(K16,L16,P16>=STANDBY_DWELL_S),"SB",IF(AND(K16,NOT(M16)),"OD",IF(AND(K16,NOT(L16),P16>=DELAY_DWELL_S),"OD","WT"))))) -> WT | S16: =IF(R16<>"",R16,Q16) -> WT
A17: 2025-09-04T08:22:27.689267Z | B17: =DATE(VALUE(LEFT(A17,4)),VALUE(MID(A17,6,2)),VALUE(MID(A17,9,2)))+TIME(VALUE(MID(A17,12,2)),VALUE(MID(A17,15,2)),VALUE(MID(A17,18,2)))+IFERROR(VALUE(MID(A17,21,6)),0)/86400000000 -> 45904.349 | C17: =B17+UTC_OFFSET_H/24 -> 45904.682 | D17: -31.981311 | E17: 115.81653 | F17: 1.2 | G17: 0 | H17: =(B18-B17)*86400 -> 5.0085325 | I17: =2*6371000*ASIN(SQRT(SIN((RADIANS(D17)-RADIANS(DEPOT_LAT))/2)^2+COS(RADIANS(DEPOT_LAT))*COS(RADIANS(D17))*SIN((RADIANS(E17)-RADIANS(DEPOT_LON))/2)^2)) -> 52.586193 | J17: =AND(WEEKDAY(C17,2)<=SERVICE_LAST_WEEKDAY,MOD(C17,1)>=SERVICE_START,MOD(C17,1)<SERVICE_END) -> TRUE | K17: =F17<SPEED_STOP_MPS -> FALSE | L17: =I17<=DEPOT_RADIUS_M -> FALSE | M17: =G17>=0 -> TRUE | N17: =H17>MAX_GAP_S -> FALSE | O17: =IF(AND(K17=K16,L17=L16),O16,O16+1) -> 3 | P17: =SUMIFS($H$2:$H$440,$O$2:$O$440,O17) -> 71.5831 | Q17: =IF(NOT(J17),"UT",IF(N17,IF(L17,"SB","OD"),IF(AND(K17,L17,P17>=STANDBY_DWELL_S),"SB",IF(AND(K17,NOT(M17)),"OD",IF(AND(K17,NOT(L17),P17>=DELAY_DWELL_S),"OD","WT"))))) -> WT | S17: =IF(R17<>"",R17,Q17) -> WT | U17: Source | V17: data/sample/positions_1.csv (439 rows, real RTK track, 5 s polling, 2025-09-04 08:21 to 08:58 UTC = 16:21 to 16:58 Perth, a Thursday). Only the columns the model uses are copied; altitude, heading, covariance type and the empty battery column are left out.
A18: 2025-09-04T08:22:32.697800Z | B18: =DATE(VALUE(LEFT(A18,4)),VALUE(MID(A18,6,2)),VALUE(MID(A18,9,2)))+TIME(VALUE(MID(A18,12,2)),VALUE(MID(A18,15,2)),VALUE(MID(A18,18,2)))+IFERROR(VALUE(MID(A18,21,6)),0)/86400000000 -> 45904.349 | C18: =B18+UTC_OFFSET_H/24 -> 45904.682 | D18: -31.981311 | E18: 115.8166 | F18: 1.35 | G18: 0 | H18: =(B19-B18)*86400 -> 5.1798722 | I18: =2*6371000*ASIN(SQRT(SIN((RADIANS(D18)-RADIANS(DEPOT_LAT))/2)^2+COS(RADIANS(DEPOT_LAT))*COS(RADIANS(D18))*SIN((RADIANS(E18)-RADIANS(DEPOT_LON))/2)^2)) -> 59.338018 | J18: =AND(WEEKDAY(C18,2)<=SERVICE_LAST_WEEKDAY,MOD(C18,1)>=SERVICE_START,MOD(C18,1)<SERVICE_END) -> TRUE | K18: =F18<SPEED_STOP_MPS -> FALSE | L18: =I18<=DEPOT_RADIUS_M -> FALSE | M18: =G18>=0 -> TRUE | N18: =H18>MAX_GAP_S -> FALSE | O18: =IF(AND(K18=K17,L18=L17),O17,O17+1) -> 3 | P18: =SUMIFS($H$2:$H$440,$O$2:$O$440,O18) -> 71.5831 | Q18: =IF(NOT(J18),"UT",IF(N18,IF(L18,"SB","OD"),IF(AND(K18,L18,P18>=STANDBY_DWELL_S),"SB",IF(AND(K18,NOT(M18)),"OD",IF(AND(K18,NOT(L18),P18>=DELAY_DWELL_S),"OD","WT"))))) -> WT | S18: =IF(R18<>"",R18,Q18) -> WT
A19: 2025-09-04T08:22:37.877672Z | B19: =DATE(VALUE(LEFT(A19,4)),VALUE(MID(A19,6,2)),VALUE(MID(A19,9,2)))+TIME(VALUE(MID(A19,12,2)),VALUE(MID(A19,15,2)),VALUE(MID(A19,18,2)))+IFERROR(VALUE(MID(A19,21,6)),0)/86400000000 -> 45904.349 | C19: =B19+UTC_OFFSET_H/24 -> 45904.682 | D19: -31.981308 | E19: 115.81667 | F19: 1.255 | G19: 0 | H19: =(B20-B19)*86400 -> 5.0058262 | I19: =2*6371000*ASIN(SQRT(SIN((RADIANS(D19)-RADIANS(DEPOT_LAT))/2)^2+COS(RADIANS(DEPOT_LAT))*COS(RADIANS(D19))*SIN((RADIANS(E19)-RADIANS(DEPOT_LON))/2)^2)) -> 65.837628 | J19: =AND(WEEKDAY(C19,2)<=SERVICE_LAST_WEEKDAY,MOD(C19,1)>=SERVICE_START,MOD(C19,1)<SERVICE_END) -> TRUE | K19: =F19<SPEED_STOP_MPS -> FALSE | L19: =I19<=DEPOT_RADIUS_M -> FALSE | M19: =G19>=0 -> TRUE | N19: =H19>MAX_GAP_S -> FALSE | O19: =IF(AND(K19=K18,L19=L18),O18,O18+1) -> 3 | P19: =SUMIFS($H$2:$H$440,$O$2:$O$440,O19) -> 71.5831 | Q19: =IF(NOT(J19),"UT",IF(N19,IF(L19,"SB","OD"),IF(AND(K19,L19,P19>=STANDBY_DWELL_S),"SB",IF(AND(K19,NOT(M19)),"OD",IF(AND(K19,NOT(L19),P19>=DELAY_DWELL_S),"OD","WT"))))) -> WT | S19: =IF(R19<>"",R19,Q19) -> WT | U19: Priority | V19: state_auto tests in this order: outside roster -> UT; telemetry gap -> SB if last seen in depot else OD; stationary in depot for the dwell -> SB; stationary with no GPS fix -> OD (GMG lists loss of GPS as an operating delay); stationary away from depot for the dwell -> OD; everything else -> WT. A row can only land in one bucket, which is what makes the buckets sum to Calendar Time.
A20: 2025-09-04T08:22:42.883498Z | B20: =DATE(VALUE(LEFT(A20,4)),VALUE(MID(A20,6,2)),VALUE(MID(A20,9,2)))+TIME(VALUE(MID(A20,12,2)),VALUE(MID(A20,15,2)),VALUE(MID(A20,18,2)))+IFERROR(VALUE(MID(A20,21,6)),0)/86400000000 -> 45904.349 | C20: =B20+UTC_OFFSET_H/24 -> 45904.682 | D20: -31.981308 | E20: 115.81673 | F20: 1.254 | G20: 0 | H20: =(B21-B20)*86400 -> 5.0098608 | I20: =2*6371000*ASIN(SQRT(SIN((RADIANS(D20)-RADIANS(DEPOT_LAT))/2)^2+COS(RADIANS(DEPOT_LAT))*COS(RADIANS(D20))*SIN((RADIANS(E20)-RADIANS(DEPOT_LON))/2)^2)) -> 72.105692 | J20: =AND(WEEKDAY(C20,2)<=SERVICE_LAST_WEEKDAY,MOD(C20,1)>=SERVICE_START,MOD(C20,1)<SERVICE_END) -> TRUE | K20: =F20<SPEED_STOP_MPS -> FALSE | L20: =I20<=DEPOT_RADIUS_M -> FALSE | M20: =G20>=0 -> TRUE | N20: =H20>MAX_GAP_S -> FALSE | O20: =IF(AND(K20=K19,L20=L19),O19,O19+1) -> 3 | P20: =SUMIFS($H$2:$H$440,$O$2:$O$440,O20) -> 71.5831 | Q20: =IF(NOT(J20),"UT",IF(N20,IF(L20,"SB","OD"),IF(AND(K20,L20,P20>=STANDBY_DWELL_S),"SB",IF(AND(K20,NOT(M20)),"OD",IF(AND(K20,NOT(L20),P20>=DELAY_DWELL_S),"OD","WT"))))) -> WT | S20: =IF(R20<>"",R20,Q20) -> WT
A21: 2025-09-04T08:22:47.893359Z | B21: =DATE(VALUE(LEFT(A21,4)),VALUE(MID(A21,6,2)),VALUE(MID(A21,9,2)))+TIME(VALUE(MID(A21,12,2)),VALUE(MID(A21,15,2)),VALUE(MID(A21,18,2)))+IFERROR(VALUE(MID(A21,21,6)),0)/86400000000 -> 45904.349 | C21: =B21+UTC_OFFSET_H/24 -> 45904.682 | D21: -31.981309 | E21: 115.8168 | F21: 1.256 | G21: 0 | H21: =(B22-B21)*86400 -> 5.1899632 | I21: =2*6371000*ASIN(SQRT(SIN((RADIANS(D21)-RADIANS(DEPOT_LAT))/2)^2+COS(RADIANS(DEPOT_LAT))*COS(RADIANS(D21))*SIN((RADIANS(E21)-RADIANS(DEPOT_LON))/2)^2)) -> 78.391516 | J21: =AND(WEEKDAY(C21,2)<=SERVICE_LAST_WEEKDAY,MOD(C21,1)>=SERVICE_START,MOD(C21,1)<SERVICE_END) -> TRUE | K21: =F21<SPEED_STOP_MPS -> FALSE | L21: =I21<=DEPOT_RADIUS_M -> FALSE | M21: =G21>=0 -> TRUE | N21: =H21>MAX_GAP_S -> FALSE | O21: =IF(AND(K21=K20,L21=L20),O20,O20+1) -> 3 | P21: =SUMIFS($H$2:$H$440,$O$2:$O$440,O21) -> 71.5831 | Q21: =IF(NOT(J21),"UT",IF(N21,IF(L21,"SB","OD"),IF(AND(K21,L21,P21>=STANDBY_DWELL_S),"SB",IF(AND(K21,NOT(M21)),"OD",IF(AND(K21,NOT(L21),P21>=DELAY_DWELL_S),"OD","WT"))))) -> WT | S21: =IF(R21<>"",R21,Q21) -> WT
A22: 2025-09-04T08:22:53.083322Z | B22: =DATE(VALUE(LEFT(A22,4)),VALUE(MID(A22,6,2)),VALUE(MID(A22,9,2)))+TIME(VALUE(MID(A22,12,2)),VALUE(MID(A22,15,2)),VALUE(MID(A22,18,2)))+IFERROR(VALUE(MID(A22,21,6)),0)/86400000000 -> 45904.349 | C22: =B22+UTC_OFFSET_H/24 -> 45904.683 | D22: -31.981312 | E22: 115.81687 | F22: 1.287 | G22: 0 | H22: =(B23-B22)*86400 -> 5.211354 | I22: =2*6371000*ASIN(SQRT(SIN((RADIANS(D22)-RADIANS(DEPOT_LAT))/2)^2+COS(RADIANS(DEPOT_LAT))*COS(RADIANS(D22))*SIN((RADIANS(E22)-RADIANS(DEPOT_LON))/2)^2)) -> 85.051995 | J22: =AND(WEEKDAY(C22,2)<=SERVICE_LAST_WEEKDAY,MOD(C22,1)>=SERVICE_START,MOD(C22,1)<SERVICE_END) -> TRUE | K22: =F22<SPEED_STOP_MPS -> FALSE | L22: =I22<=DEPOT_RADIUS_M -> FALSE | M22: =G22>=0 -> TRUE | N22: =H22>MAX_GAP_S -> FALSE | O22: =IF(AND(K22=K21,L22=L21),O21,O21+1) -> 3 | P22: =SUMIFS($H$2:$H$440,$O$2:$O$440,O22) -> 71.5831 | Q22: =IF(NOT(J22),"UT",IF(N22,IF(L22,"SB","OD"),IF(AND(K22,L22,P22>=STANDBY_DWELL_S),"SB",IF(AND(K22,NOT(M22)),"OD",IF(AND(K22,NOT(L22),P22>=DELAY_DWELL_S),"OD","WT"))))) -> WT | S22: =IF(R22<>"",R22,Q22) -> WT
A23: 2025-09-04T08:22:58.294676Z | B23: =DATE(VALUE(LEFT(A23,4)),VALUE(MID(A23,6,2)),VALUE(MID(A23,9,2)))+TIME(VALUE(MID(A23,12,2)),VALUE(MID(A23,15,2)),VALUE(MID(A23,18,2)))+IFERROR(VALUE(MID(A23,21,6)),0)/86400000000 -> 45904.349 | C23: =B23+UTC_OFFSET_H/24 -> 45904.683 | D23: -31.981314 | E23: 115.81694 | F23: 1.228 | G23: 0 | H23: =(B24-B23)*86400 -> 5.0101663 | I23: =2*6371000*ASIN(SQRT(SIN((RADIANS(D23)-RADIANS(DEPOT_LAT))/2)^2+COS(RADIANS(DEPOT_LAT))*COS(RADIANS(D23))*SIN((RADIANS(E23)-RADIANS(DEPOT_LON))/2)^2)) -> 91.444677 | J23: =AND(WEEKDAY(C23,2)<=SERVICE_LAST_WEEKDAY,MOD(C23,1)>=SERVICE_START,MOD(C23,1)<SERVICE_END) -> TRUE | K23: =F23<SPEED_STOP_MPS -> FALSE | L23: =I23<=DEPOT_RADIUS_M -> FALSE | M23: =G23>=0 -> TRUE | N23: =H23>MAX_GAP_S -> FALSE | O23: =IF(AND(K23=K22,L23=L22),O22,O22+1) -> 3 | P23: =SUMIFS($H$2:$H$440,$O$2:$O$440,O23) -> 71.5831 | Q23: =IF(NOT(J23),"UT",IF(N23,IF(L23,"SB","OD"),IF(AND(K23,L23,P23>=STANDBY_DWELL_S),"SB",IF(AND(K23,NOT(M23)),"OD",IF(AND(K23,NOT(L23),P23>=DELAY_DWELL_S),"OD","WT"))))) -> WT | S23: =IF(R23<>"",R23,Q23) -> WT
